[2017-04-11 13:07:47 +0800] [1] [INFO] Starting gunicorn 19.7.1
[2017-04-11 13:07:47 +0800] [1] [INFO] Listening at: http://0.0.0.0:10080 (1)
[2017-04-11 13:07:47 +0800] [1] [INFO] Using worker: sync
[2017-04-11 13:07:47 +0800] [8] [INFO] Booting worker with pid: 8
[2017-04-11 13:07:47 +0800] [9] [INFO] Booting worker with pid: 9
[2017-04-11 13:11:38,842] ERROR in app: Exception on /admin/ [GET]
Traceback (most recent call last):
  File "/usr/lib64/python3.5/site-packages/flask/app.py", line 1982, in wsgi_app
    response = self.full_dispatch_request()
  File "/usr/lib64/python3.5/site-packages/flask/app.py", line 1614, in full_dispatch_request
    rv = self.handle_user_exception(e)
  File "/usr/lib64/python3.5/site-packages/flask/app.py", line 1517, in handle_user_exception
    reraise(exc_type, exc_value, tb)
  File "/usr/lib64/python3.5/site-packages/flask/_compat.py", line 33, in reraise
    raise value
  File "/usr/lib64/python3.5/site-packages/flask/app.py", line 1612, in full_dispatch_request
    rv = self.dispatch_request()
  File "/usr/lib64/python3.5/site-packages/flask/app.py", line 1598, in dispatch_request
    return self.view_functions[rule.endpoint](**req.view_args)
  File "/usr/lib/python3.5/site-packages/flask_admin/base.py", line 69, in inner
    return self._run_view(f, *args, **kwargs)
  File "/usr/lib/python3.5/site-packages/flask_admin/base.py", line 368, in _run_view
    return fn(self, *args, **kwargs)
  File "/usr/lib/python3.5/site-packages/flask_admin/base.py", line 452, in index
    return self.render(self._template)
  File "/usr/lib/python3.5/site-packages/flask_admin/base.py", line 308, in render
    return render_template(template, **kwargs)
  File "/usr/lib64/python3.5/site-packages/flask/templating.py", line 134, in render_template
    context, ctx.app)
  File "/usr/lib64/python3.5/site-packages/flask/templating.py", line 116, in _render
    rv = template.render(context)
  File "/usr/lib/python3.5/site-packages/jinja2/environment.py", line 1008, in render
    return self.environment.handle_exception(exc_info, True)
  File "/usr/lib/python3.5/site-packages/jinja2/environment.py", line 780, in handle_exception
    reraise(exc_type, exc_value, tb)
  File "/usr/lib/python3.5/site-packages/jinja2/_compat.py", line 37, in reraise
    raise value.with_traceback(tb)
  File "/usr/lib/python3.5/site-packages/flask_admin/templates/bootstrap3/admin/index.html", line 1, in top-level template code
    {% extends 'admin/master.html' %}
  File "/usr/lib/python3.5/site-packages/flask_admin/templates/bootstrap3/admin/master.html", line 1, in top-level template code
    {% extends admin_base_template %}
  File "/usr/lib/python3.5/site-packages/flask_admin/templates/bootstrap3/admin/base.html", line 37, in top-level template code
    {% block page_body %}
  File "/usr/lib/python3.5/site-packages/flask_admin/templates/bootstrap3/admin/base.html", line 54, in block "page_body"
    {% block main_menu %}
  File "/usr/lib/python3.5/site-packages/flask_admin/templates/bootstrap3/admin/base.html", line 56, in block "main_menu"
    {{ layout.menu() }}
  File "/usr/lib/python3.5/site-packages/jinja2/runtime.py", line 553, in _invoke
    rv = self._func(*arguments)
  File "/usr/lib/python3.5/site-packages/flask_admin/templates/bootstrap3/admin/layout.html", line 47, in template
    {%- if item.is_accessible() and item.is_visible() -%}
  File "/usr/lib/python3.5/site-packages/flask_admin/menu.py", line 126, in is_accessible
    return self._view.is_accessible()
  File "/opt/weeklyreport/app/main/views.py", line 131, in is_accessible
    return current_user.is_admin
  File "/usr/lib/python3.5/site-packages/werkzeug/local.py", line 347, in __getattr__
    return getattr(self._get_current_object(), name)
AttributeError: 'AnonymousUserMixin' object has no attribute 'is_admin'
[2017-04-11 13:11:42,333] ERROR in app: Exception on /my_report/ [GET]
Traceback (most recent call last):
  File "/usr/lib64/python3.5/site-packages/flask/app.py", line 1982, in wsgi_app
    response = self.full_dispatch_request()
  File "/usr/lib64/python3.5/site-packages/flask/app.py", line 1614, in full_dispatch_request
    rv = self.handle_user_exception(e)
  File "/usr/lib64/python3.5/site-packages/flask/app.py", line 1517, in handle_user_exception
    reraise(exc_type, exc_value, tb)
  File "/usr/lib64/python3.5/site-packages/flask/_compat.py", line 33, in reraise
    raise value
  File "/usr/lib64/python3.5/site-packages/flask/app.py", line 1612, in full_dispatch_request
    rv = self.dispatch_request()
  File "/usr/lib64/python3.5/site-packages/flask/app.py", line 1598, in dispatch_request
    return self.view_functions[rule.endpoint](**req.view_args)
  File "/opt/weeklyreport/app/utils.py", line 13, in decorated_function
    if not current_user.can(permission):
  File "/usr/lib/python3.5/site-packages/werkzeug/local.py", line 347, in __getattr__
    return getattr(self._get_current_object(), name)
AttributeError: 'AnonymousUserMixin' object has no attribute 'can'
[2017-04-11 13:11:45,444] ERROR in app: Exception on /admin/user/ [GET]
Traceback (most recent call last):
  File "/usr/lib64/python3.5/site-packages/flask/app.py", line 1982, in wsgi_app
    response = self.full_dispatch_request()
  File "/usr/lib64/python3.5/site-packages/flask/app.py", line 1614, in full_dispatch_request
    rv = self.handle_user_exception(e)
  File "/usr/lib64/python3.5/site-packages/flask/app.py", line 1517, in handle_user_exception
    reraise(exc_type, exc_value, tb)
  File "/usr/lib64/python3.5/site-packages/flask/_compat.py", line 33, in reraise
    raise value
  File "/usr/lib64/python3.5/site-packages/flask/app.py", line 1612, in full_dispatch_request
    rv = self.dispatch_request()
  File "/usr/lib64/python3.5/site-packages/flask/app.py", line 1598, in dispatch_request
    return self.view_functions[rule.endpoint](**req.view_args)
  File "/usr/lib/python3.5/site-packages/flask_admin/base.py", line 65, in inner
    abort = self._handle_view(f.__name__, **kwargs)
  File "/usr/lib/python3.5/site-packages/flask_admin/base.py", line 353, in _handle_view
    if not self.is_accessible():
  File "/opt/weeklyreport/app/main/views.py", line 131, in is_accessible
    return current_user.is_admin
  File "/usr/lib/python3.5/site-packages/werkzeug/local.py", line 347, in __getattr__
    return getattr(self._get_current_object(), name)
AttributeError: 'AnonymousUserMixin' object has no attribute 'is_admin'
[2017-04-11 13:24:52 +0800] [1] [INFO] Handling signal: term
[2017-04-11 13:24:52 +0800] [8] [INFO] Worker exiting (pid: 8)
[2017-04-11 13:24:52 +0800] [9] [INFO] Worker exiting (pid: 9)
[2017-04-11 13:24:53 +0800] [1] [INFO] Shutting down: Master
[2017-04-11 13:24:54 +0800] [1] [INFO] Starting gunicorn 19.7.1
[2017-04-11 13:24:54 +0800] [1] [INFO] Listening at: http://0.0.0.0:10080 (1)
[2017-04-11 13:24:54 +0800] [1] [INFO] Using worker: sync
[2017-04-11 13:24:54 +0800] [8] [INFO] Booting worker with pid: 8
[2017-04-11 13:24:54 +0800] [9] [INFO] Booting worker with pid: 9
[2017-04-11 13:28:19 +0800] [1] [INFO] Handling signal: term
[2017-04-11 13:28:19 +0800] [9] [INFO] Worker exiting (pid: 9)
[2017-04-11 13:28:19 +0800] [8] [INFO] Worker exiting (pid: 8)
[2017-04-11 13:28:20 +0800] [1] [INFO] Shutting down: Master
[2017-04-11 13:28:21 +0800] [1] [INFO] Starting gunicorn 19.7.1
[2017-04-11 13:28:21 +0800] [1] [INFO] Listening at: http://0.0.0.0:10080 (1)
[2017-04-11 13:28:21 +0800] [1] [INFO] Using worker: sync
[2017-04-11 13:28:21 +0800] [9] [INFO] Booting worker with pid: 9
[2017-04-11 13:28:21 +0800] [10] [INFO] Booting worker with pid: 10
[2017-04-11 13:28:30,614] ERROR in app: Exception on /auth/login [POST]
Traceback (most recent call last):
  File "/usr/lib64/python3.5/site-packages/flask/app.py", line 1982, in wsgi_app
    response = self.full_dispatch_request()
  File "/usr/lib64/python3.5/site-packages/flask/app.py", line 1614, in full_dispatch_request
    rv = self.handle_user_exception(e)
  File "/usr/lib64/python3.5/site-packages/flask/app.py", line 1517, in handle_user_exception
    reraise(exc_type, exc_value, tb)
  File "/usr/lib64/python3.5/site-packages/flask/_compat.py", line 33, in reraise
    raise value
  File "/usr/lib64/python3.5/site-packages/flask/app.py", line 1612, in full_dispatch_request
    rv = self.dispatch_request()
  File "/usr/lib64/python3.5/site-packages/flask/app.py", line 1598, in dispatch_request
    return self.view_functions[rule.endpoint](**req.view_args)
  File "/opt/weeklyreport/app/auth/views.py", line 17, in login
    flash('you have logged in')
  File "/usr/lib64/python3.5/site-packages/flask/helpers.py", line 386, in flash
    flashes.append((category, message))
  File "/usr/lib/python3.5/site-packages/mongoengine/base/datastructures.py", line 170, in append
    self._mark_as_changed()
  File "/usr/lib/python3.5/site-packages/mongoengine/base/datastructures.py", line 198, in _mark_as_changed
    if hasattr(self._instance, '_mark_as_changed'):
ReferenceError: weakly-referenced object no longer exists
[2017-04-11 13:28:38,998] ERROR in app: Exception on /auth/login [POST]
Traceback (most recent call last):
  File "/usr/lib64/python3.5/site-packages/flask/app.py", line 1982, in wsgi_app
    response = self.full_dispatch_request()
  File "/usr/lib64/python3.5/site-packages/flask/app.py", line 1614, in full_dispatch_request
    rv = self.handle_user_exception(e)
  File "/usr/lib64/python3.5/site-packages/flask/app.py", line 1517, in handle_user_exception
    reraise(exc_type, exc_value, tb)
  File "/usr/lib64/python3.5/site-packages/flask/_compat.py", line 33, in reraise
    raise value
  File "/usr/lib64/python3.5/site-packages/flask/app.py", line 1612, in full_dispatch_request
    rv = self.dispatch_request()
  File "/usr/lib64/python3.5/site-packages/flask/app.py", line 1598, in dispatch_request
    return self.view_functions[rule.endpoint](**req.view_args)
  File "/opt/weeklyreport/app/auth/views.py", line 17, in login
    flash('you have logged in')
  File "/usr/lib64/python3.5/site-packages/flask/helpers.py", line 386, in flash
    flashes.append((category, message))
  File "/usr/lib/python3.5/site-packages/mongoengine/base/datastructures.py", line 170, in append
    self._mark_as_changed()
  File "/usr/lib/python3.5/site-packages/mongoengine/base/datastructures.py", line 198, in _mark_as_changed
    if hasattr(self._instance, '_mark_as_changed'):
ReferenceError: weakly-referenced object no longer exists
[2017-04-11 13:28:50,448] ERROR in app: Exception on /auth/login [POST]
Traceback (most recent call last):
  File "/usr/lib64/python3.5/site-packages/flask/app.py", line 1982, in wsgi_app
    response = self.full_dispatch_request()
  File "/usr/lib64/python3.5/site-packages/flask/app.py", line 1614, in full_dispatch_request
    rv = self.handle_user_exception(e)
  File "/usr/lib64/python3.5/site-packages/flask/app.py", line 1517, in handle_user_exception
    reraise(exc_type, exc_value, tb)
  File "/usr/lib64/python3.5/site-packages/flask/_compat.py", line 33, in reraise
    raise value
  File "/usr/lib64/python3.5/site-packages/flask/app.py", line 1612, in full_dispatch_request
    rv = self.dispatch_request()
  File "/usr/lib64/python3.5/site-packages/flask/app.py", line 1598, in dispatch_request
    return self.view_functions[rule.endpoint](**req.view_args)
  File "/opt/weeklyreport/app/auth/views.py", line 17, in login
    flash('you have logged in')
  File "/usr/lib64/python3.5/site-packages/flask/helpers.py", line 386, in flash
    flashes.append((category, message))
  File "/usr/lib/python3.5/site-packages/mongoengine/base/datastructures.py", line 170, in append
    self._mark_as_changed()
  File "/usr/lib/python3.5/site-packages/mongoengine/base/datastructures.py", line 198, in _mark_as_changed
    if hasattr(self._instance, '_mark_as_changed'):
ReferenceError: weakly-referenced object no longer exists
[2017-04-11 13:28:57 +0800] [1] [INFO] Handling signal: term
[2017-04-11 13:28:57 +0800] [10] [INFO] Worker exiting (pid: 10)
[2017-04-11 13:28:57 +0800] [9] [INFO] Worker exiting (pid: 9)
[2017-04-11 13:28:57 +0800] [1] [INFO] Shutting down: Master
[2017-04-11 13:28:58 +0800] [1] [INFO] Starting gunicorn 19.7.1
[2017-04-11 13:28:58 +0800] [1] [INFO] Listening at: http://0.0.0.0:10080 (1)
[2017-04-11 13:28:58 +0800] [1] [INFO] Using worker: sync
[2017-04-11 13:28:58 +0800] [9] [INFO] Booting worker with pid: 9
[2017-04-11 13:28:58 +0800] [10] [INFO] Booting worker with pid: 10
[2017-04-11 14:02:27 +0800] [1] [INFO] Handling signal: term
[2017-04-11 14:02:27 +0800] [9] [INFO] Worker exiting (pid: 9)
[2017-04-11 14:02:27 +0800] [10] [INFO] Worker exiting (pid: 10)
[2017-04-11 14:02:27 +0800] [1] [INFO] Shutting down: Master
[2017-04-11 14:02:28 +0800] [1] [INFO] Starting gunicorn 19.7.1
[2017-04-11 14:02:28 +0800] [1] [INFO] Listening at: http://0.0.0.0:10080 (1)
[2017-04-11 14:02:28 +0800] [1] [INFO] Using worker: sync
[2017-04-11 14:02:28 +0800] [8] [INFO] Booting worker with pid: 8
[2017-04-11 14:02:28 +0800] [9] [INFO] Booting worker with pid: 9
[2017-04-11 14:02:28 +0800] [8] [ERROR] Exception in worker process
Traceback (most recent call last):
  File "/usr/lib/python3.5/site-packages/gunicorn/arbiter.py", line 578, in spawn_worker
    worker.init_process()
  File "/usr/lib/python3.5/site-packages/gunicorn/workers/base.py", line 126, in init_process
    self.load_wsgi()
  File "/usr/lib/python3.5/site-packages/gunicorn/workers/base.py", line 135, in load_wsgi
    self.wsgi = self.app.wsgi()
  File "/usr/lib/python3.5/site-packages/gunicorn/app/base.py", line 67, in wsgi
    self.callable = self.load()
  File "/usr/lib/python3.5/site-packages/gunicorn/app/wsgiapp.py", line 65, in load
    return self.load_wsgiapp()
  File "/usr/lib/python3.5/site-packages/gunicorn/app/wsgiapp.py", line 52, in load_wsgiapp
    return util.import_app(self.app_uri)
  File "/usr/lib/python3.5/site-packages/gunicorn/util.py", line 352, in import_app
    __import__(module)
  File "/opt/weeklyreport/wsgi.py", line 5, in <module>
    app = create_app(os.getenv('FLASK_CONFIG') or 'default')
  File "/opt/weeklyreport/app/__init__.py", line 43, in create_app
    app.jinja_env.add_extension("chartkick.ext.charts")
  File "/usr/lib/python3.5/site-packages/jinja2/environment.py", line 345, in add_extension
    self.extensions.update(load_extensions(self, [extension]))
  File "/usr/lib/python3.5/site-packages/jinja2/environment.py", line 85, in load_extensions
    extension = import_string(extension)
  File "/usr/lib/python3.5/site-packages/jinja2/utils.py", line 143, in import_string
    return getattr(__import__(module, None, None, [obj]), obj)
ImportError: No module named 'chartkick'
[2017-04-11 14:02:28 +0800] [8] [INFO] Worker exiting (pid: 8)
[2017-04-11 14:02:28 +0800] [9] [ERROR] Exception in worker process
Traceback (most recent call last):
  File "/usr/lib/python3.5/site-packages/gunicorn/arbiter.py", line 578, in spawn_worker
    worker.init_process()
  File "/usr/lib/python3.5/site-packages/gunicorn/workers/base.py", line 126, in init_process
    self.load_wsgi()
  File "/usr/lib/python3.5/site-packages/gunicorn/workers/base.py", line 135, in load_wsgi
    self.wsgi = self.app.wsgi()
  File "/usr/lib/python3.5/site-packages/gunicorn/app/base.py", line 67, in wsgi
    self.callable = self.load()
  File "/usr/lib/python3.5/site-packages/gunicorn/app/wsgiapp.py", line 65, in load
    return self.load_wsgiapp()
  File "/usr/lib/python3.5/site-packages/gunicorn/app/wsgiapp.py", line 52, in load_wsgiapp
    return util.import_app(self.app_uri)
  File "/usr/lib/python3.5/site-packages/gunicorn/util.py", line 352, in import_app
    __import__(module)
  File "/opt/weeklyreport/wsgi.py", line 5, in <module>
    app = create_app(os.getenv('FLASK_CONFIG') or 'default')
  File "/opt/weeklyreport/app/__init__.py", line 43, in create_app
    app.jinja_env.add_extension("chartkick.ext.charts")
  File "/usr/lib/python3.5/site-packages/jinja2/environment.py", line 345, in add_extension
    self.extensions.update(load_extensions(self, [extension]))
  File "/usr/lib/python3.5/site-packages/jinja2/environment.py", line 85, in load_extensions
    extension = import_string(extension)
  File "/usr/lib/python3.5/site-packages/jinja2/utils.py", line 143, in import_string
    return getattr(__import__(module, None, None, [obj]), obj)
ImportError: No module named 'chartkick'
[2017-04-11 14:02:28 +0800] [9] [INFO] Worker exiting (pid: 9)
[2017-04-11 14:02:29 +0800] [1] [INFO] Starting gunicorn 19.7.1
[2017-04-11 14:02:29 +0800] [1] [INFO] Listening at: http://0.0.0.0:10080 (1)
[2017-04-11 14:02:29 +0800] [1] [INFO] Using worker: sync
[2017-04-11 14:02:29 +0800] [8] [INFO] Booting worker with pid: 8
[2017-04-11 14:02:29 +0800] [9] [INFO] Booting worker with pid: 9
[2017-04-11 14:02:30 +0800] [8] [ERROR] Exception in worker process
Traceback (most recent call last):
  File "/usr/lib/python3.5/site-packages/gunicorn/arbiter.py", line 578, in spawn_worker
    worker.init_process()
  File "/usr/lib/python3.5/site-packages/gunicorn/workers/base.py", line 126, in init_process
    self.load_wsgi()
  File "/usr/lib/python3.5/site-packages/gunicorn/workers/base.py", line 135, in load_wsgi
    self.wsgi = self.app.wsgi()
  File "/usr/lib/python3.5/site-packages/gunicorn/app/base.py", line 67, in wsgi
    self.callable = self.load()
  File "/usr/lib/python3.5/site-packages/gunicorn/app/wsgiapp.py", line 65, in load
    return self.load_wsgiapp()
  File "/usr/lib/python3.5/site-packages/gunicorn/app/wsgiapp.py", line 52, in load_wsgiapp
    return util.import_app(self.app_uri)
  File "/usr/lib/python3.5/site-packages/gunicorn/util.py", line 352, in import_app
    __import__(module)
  File "/opt/weeklyreport/wsgi.py", line 5, in <module>
    app = create_app(os.getenv('FLASK_CONFIG') or 'default')
  File "/opt/weeklyreport/app/__init__.py", line 43, in create_app
    app.jinja_env.add_extension("chartkick.ext.charts")
  File "/usr/lib/python3.5/site-packages/jinja2/environment.py", line 345, in add_extension
    self.extensions.update(load_extensions(self, [extension]))
  File "/usr/lib/python3.5/site-packages/jinja2/environment.py", line 85, in load_extensions
    extension = import_string(extension)
  File "/usr/lib/python3.5/site-packages/jinja2/utils.py", line 143, in import_string
    return getattr(__import__(module, None, None, [obj]), obj)
ImportError: No module named 'chartkick'
[2017-04-11 14:02:30 +0800] [8] [INFO] Worker exiting (pid: 8)
[2017-04-11 14:02:30 +0800] [9] [ERROR] Exception in worker process
Traceback (most recent call last):
  File "/usr/lib/python3.5/site-packages/gunicorn/arbiter.py", line 578, in spawn_worker
    worker.init_process()
  File "/usr/lib/python3.5/site-packages/gunicorn/workers/base.py", line 126, in init_process
    self.load_wsgi()
  File "/usr/lib/python3.5/site-packages/gunicorn/workers/base.py", line 135, in load_wsgi
    self.wsgi = self.app.wsgi()
  File "/usr/lib/python3.5/site-packages/gunicorn/app/base.py", line 67, in wsgi
    self.callable = self.load()
  File "/usr/lib/python3.5/site-packages/gunicorn/app/wsgiapp.py", line 65, in load
    return self.load_wsgiapp()
  File "/usr/lib/python3.5/site-packages/gunicorn/app/wsgiapp.py", line 52, in load_wsgiapp
    return util.import_app(self.app_uri)
  File "/usr/lib/python3.5/site-packages/gunicorn/util.py", line 352, in import_app
    __import__(module)
  File "/opt/weeklyreport/wsgi.py", line 5, in <module>
    app = create_app(os.getenv('FLASK_CONFIG') or 'default')
  File "/opt/weeklyreport/app/__init__.py", line 43, in create_app
    app.jinja_env.add_extension("chartkick.ext.charts")
  File "/usr/lib/python3.5/site-packages/jinja2/environment.py", line 345, in add_extension
    self.extensions.update(load_extensions(self, [extension]))
  File "/usr/lib/python3.5/site-packages/jinja2/environment.py", line 85, in load_extensions
    extension = import_string(extension)
  File "/usr/lib/python3.5/site-packages/jinja2/utils.py", line 143, in import_string
    return getattr(__import__(module, None, None, [obj]), obj)
ImportError: No module named 'chartkick'
[2017-04-11 14:02:30 +0800] [9] [INFO] Worker exiting (pid: 9)
[2017-04-11 14:02:31 +0800] [1] [INFO] Starting gunicorn 19.7.1
[2017-04-11 14:02:31 +0800] [1] [INFO] Listening at: http://0.0.0.0:10080 (1)
[2017-04-11 14:02:31 +0800] [1] [INFO] Using worker: sync
[2017-04-11 14:02:31 +0800] [9] [INFO] Booting worker with pid: 9
[2017-04-11 14:02:31 +0800] [10] [INFO] Booting worker with pid: 10
[2017-04-11 14:02:31 +0800] [9] [ERROR] Exception in worker process
Traceback (most recent call last):
  File "/usr/lib/python3.5/site-packages/gunicorn/arbiter.py", line 578, in spawn_worker
    worker.init_process()
  File "/usr/lib/python3.5/site-packages/gunicorn/workers/base.py", line 126, in init_process
    self.load_wsgi()
  File "/usr/lib/python3.5/site-packages/gunicorn/workers/base.py", line 135, in load_wsgi
    self.wsgi = self.app.wsgi()
  File "/usr/lib/python3.5/site-packages/gunicorn/app/base.py", line 67, in wsgi
    self.callable = self.load()
  File "/usr/lib/python3.5/site-packages/gunicorn/app/wsgiapp.py", line 65, in load
    return self.load_wsgiapp()
  File "/usr/lib/python3.5/site-packages/gunicorn/app/wsgiapp.py", line 52, in load_wsgiapp
    return util.import_app(self.app_uri)
  File "/usr/lib/python3.5/site-packages/gunicorn/util.py", line 352, in import_app
    __import__(module)
  File "/opt/weeklyreport/wsgi.py", line 5, in <module>
    app = create_app(os.getenv('FLASK_CONFIG') or 'default')
  File "/opt/weeklyreport/app/__init__.py", line 43, in create_app
    app.jinja_env.add_extension("chartkick.ext.charts")
  File "/usr/lib/python3.5/site-packages/jinja2/environment.py", line 345, in add_extension
    self.extensions.update(load_extensions(self, [extension]))
  File "/usr/lib/python3.5/site-packages/jinja2/environment.py", line 85, in load_extensions
    extension = import_string(extension)
  File "/usr/lib/python3.5/site-packages/jinja2/utils.py", line 143, in import_string
    return getattr(__import__(module, None, None, [obj]), obj)
ImportError: No module named 'chartkick'
[2017-04-11 14:02:31 +0800] [9] [INFO] Worker exiting (pid: 9)
[2017-04-11 14:02:31 +0800] [10] [ERROR] Exception in worker process
Traceback (most recent call last):
  File "/usr/lib/python3.5/site-packages/gunicorn/arbiter.py", line 578, in spawn_worker
    worker.init_process()
  File "/usr/lib/python3.5/site-packages/gunicorn/workers/base.py", line 126, in init_process
    self.load_wsgi()
  File "/usr/lib/python3.5/site-packages/gunicorn/workers/base.py", line 135, in load_wsgi
    self.wsgi = self.app.wsgi()
  File "/usr/lib/python3.5/site-packages/gunicorn/app/base.py", line 67, in wsgi
    self.callable = self.load()
  File "/usr/lib/python3.5/site-packages/gunicorn/app/wsgiapp.py", line 65, in load
    return self.load_wsgiapp()
  File "/usr/lib/python3.5/site-packages/gunicorn/app/wsgiapp.py", line 52, in load_wsgiapp
    return util.import_app(self.app_uri)
  File "/usr/lib/python3.5/site-packages/gunicorn/util.py", line 352, in import_app
    __import__(module)
  File "/opt/weeklyreport/wsgi.py", line 5, in <module>
    app = create_app(os.getenv('FLASK_CONFIG') or 'default')
  File "/opt/weeklyreport/app/__init__.py", line 43, in create_app
    app.jinja_env.add_extension("chartkick.ext.charts")
  File "/usr/lib/python3.5/site-packages/jinja2/environment.py", line 345, in add_extension
    self.extensions.update(load_extensions(self, [extension]))
  File "/usr/lib/python3.5/site-packages/jinja2/environment.py", line 85, in load_extensions
    extension = import_string(extension)
  File "/usr/lib/python3.5/site-packages/jinja2/utils.py", line 143, in import_string
    return getattr(__import__(module, None, None, [obj]), obj)
ImportError: No module named 'chartkick'
[2017-04-11 14:02:31 +0800] [10] [INFO] Worker exiting (pid: 10)
[2017-04-11 14:02:32 +0800] [1] [INFO] Shutting down: Master
[2017-04-11 14:02:32 +0800] [1] [INFO] Reason: Worker failed to boot.
[2017-04-11 14:02:33 +0800] [1] [INFO] Starting gunicorn 19.7.1
[2017-04-11 14:02:33 +0800] [1] [INFO] Listening at: http://0.0.0.0:10080 (1)
[2017-04-11 14:02:33 +0800] [1] [INFO] Using worker: sync
[2017-04-11 14:02:33 +0800] [8] [INFO] Booting worker with pid: 8
[2017-04-11 14:02:33 +0800] [9] [INFO] Booting worker with pid: 9
[2017-04-11 14:02:33 +0800] [8] [ERROR] Exception in worker process
Traceback (most recent call last):
  File "/usr/lib/python3.5/site-packages/gunicorn/arbiter.py", line 578, in spawn_worker
    worker.init_process()
  File "/usr/lib/python3.5/site-packages/gunicorn/workers/base.py", line 126, in init_process
    self.load_wsgi()
  File "/usr/lib/python3.5/site-packages/gunicorn/workers/base.py", line 135, in load_wsgi
    self.wsgi = self.app.wsgi()
  File "/usr/lib/python3.5/site-packages/gunicorn/app/base.py", line 67, in wsgi
    self.callable = self.load()
  File "/usr/lib/python3.5/site-packages/gunicorn/app/wsgiapp.py", line 65, in load
    return self.load_wsgiapp()
  File "/usr/lib/python3.5/site-packages/gunicorn/app/wsgiapp.py", line 52, in load_wsgiapp
    return util.import_app(self.app_uri)
  File "/usr/lib/python3.5/site-packages/gunicorn/util.py", line 352, in import_app
    __import__(module)
  File "/opt/weeklyreport/wsgi.py", line 5, in <module>
    app = create_app(os.getenv('FLASK_CONFIG') or 'default')
  File "/opt/weeklyreport/app/__init__.py", line 43, in create_app
    app.jinja_env.add_extension("chartkick.ext.charts")
  File "/usr/lib/python3.5/site-packages/jinja2/environment.py", line 345, in add_extension
    self.extensions.update(load_extensions(self, [extension]))
  File "/usr/lib/python3.5/site-packages/jinja2/environment.py", line 85, in load_extensions
    extension = import_string(extension)
  File "/usr/lib/python3.5/site-packages/jinja2/utils.py", line 143, in import_string
    return getattr(__import__(module, None, None, [obj]), obj)
ImportError: No module named 'chartkick'
[2017-04-11 14:02:33 +0800] [8] [INFO] Worker exiting (pid: 8)
[2017-04-11 14:02:33 +0800] [9] [ERROR] Exception in worker process
Traceback (most recent call last):
  File "/usr/lib/python3.5/site-packages/gunicorn/arbiter.py", line 578, in spawn_worker
    worker.init_process()
  File "/usr/lib/python3.5/site-packages/gunicorn/workers/base.py", line 126, in init_process
    self.load_wsgi()
  File "/usr/lib/python3.5/site-packages/gunicorn/workers/base.py", line 135, in load_wsgi
    self.wsgi = self.app.wsgi()
  File "/usr/lib/python3.5/site-packages/gunicorn/app/base.py", line 67, in wsgi
    self.callable = self.load()
  File "/usr/lib/python3.5/site-packages/gunicorn/app/wsgiapp.py", line 65, in load
    return self.load_wsgiapp()
  File "/usr/lib/python3.5/site-packages/gunicorn/app/wsgiapp.py", line 52, in load_wsgiapp
    return util.import_app(self.app_uri)
  File "/usr/lib/python3.5/site-packages/gunicorn/util.py", line 352, in import_app
    __import__(module)
  File "/opt/weeklyreport/wsgi.py", line 5, in <module>
    app = create_app(os.getenv('FLASK_CONFIG') or 'default')
  File "/opt/weeklyreport/app/__init__.py", line 43, in create_app
    app.jinja_env.add_extension("chartkick.ext.charts")
  File "/usr/lib/python3.5/site-packages/jinja2/environment.py", line 345, in add_extension
    self.extensions.update(load_extensions(self, [extension]))
  File "/usr/lib/python3.5/site-packages/jinja2/environment.py", line 85, in load_extensions
    extension = import_string(extension)
  File "/usr/lib/python3.5/site-packages/jinja2/utils.py", line 143, in import_string
    return getattr(__import__(module, None, None, [obj]), obj)
ImportError: No module named 'chartkick'
[2017-04-11 14:02:33 +0800] [9] [INFO] Worker exiting (pid: 9)
[2017-04-11 14:02:35 +0800] [1] [INFO] Starting gunicorn 19.7.1
[2017-04-11 14:02:35 +0800] [1] [INFO] Listening at: http://0.0.0.0:10080 (1)
[2017-04-11 14:02:35 +0800] [1] [INFO] Using worker: sync
[2017-04-11 14:02:35 +0800] [8] [INFO] Booting worker with pid: 8
[2017-04-11 14:02:35 +0800] [9] [INFO] Booting worker with pid: 9
[2017-04-11 14:02:35 +0800] [8] [ERROR] Exception in worker process
Traceback (most recent call last):
  File "/usr/lib/python3.5/site-packages/gunicorn/arbiter.py", line 578, in spawn_worker
    worker.init_process()
  File "/usr/lib/python3.5/site-packages/gunicorn/workers/base.py", line 126, in init_process
    self.load_wsgi()
  File "/usr/lib/python3.5/site-packages/gunicorn/workers/base.py", line 135, in load_wsgi
    self.wsgi = self.app.wsgi()
  File "/usr/lib/python3.5/site-packages/gunicorn/app/base.py", line 67, in wsgi
    self.callable = self.load()
  File "/usr/lib/python3.5/site-packages/gunicorn/app/wsgiapp.py", line 65, in load
    return self.load_wsgiapp()
  File "/usr/lib/python3.5/site-packages/gunicorn/app/wsgiapp.py", line 52, in load_wsgiapp
    return util.import_app(self.app_uri)
  File "/usr/lib/python3.5/site-packages/gunicorn/util.py", line 352, in import_app
    __import__(module)
  File "/opt/weeklyreport/wsgi.py", line 5, in <module>
    app = create_app(os.getenv('FLASK_CONFIG') or 'default')
  File "/opt/weeklyreport/app/__init__.py", line 43, in create_app
    app.jinja_env.add_extension("chartkick.ext.charts")
  File "/usr/lib/python3.5/site-packages/jinja2/environment.py", line 345, in add_extension
    self.extensions.update(load_extensions(self, [extension]))
  File "/usr/lib/python3.5/site-packages/jinja2/environment.py", line 85, in load_extensions
    extension = import_string(extension)
  File "/usr/lib/python3.5/site-packages/jinja2/utils.py", line 143, in import_string
    return getattr(__import__(module, None, None, [obj]), obj)
ImportError: No module named 'chartkick'
[2017-04-11 14:02:35 +0800] [8] [INFO] Worker exiting (pid: 8)
[2017-04-11 14:02:35 +0800] [9] [ERROR] Exception in worker process
Traceback (most recent call last):
  File "/usr/lib/python3.5/site-packages/gunicorn/arbiter.py", line 578, in spawn_worker
    worker.init_process()
  File "/usr/lib/python3.5/site-packages/gunicorn/workers/base.py", line 126, in init_process
    self.load_wsgi()
  File "/usr/lib/python3.5/site-packages/gunicorn/workers/base.py", line 135, in load_wsgi
    self.wsgi = self.app.wsgi()
  File "/usr/lib/python3.5/site-packages/gunicorn/app/base.py", line 67, in wsgi
    self.callable = self.load()
  File "/usr/lib/python3.5/site-packages/gunicorn/app/wsgiapp.py", line 65, in load
    return self.load_wsgiapp()
  File "/usr/lib/python3.5/site-packages/gunicorn/app/wsgiapp.py", line 52, in load_wsgiapp
    return util.import_app(self.app_uri)
  File "/usr/lib/python3.5/site-packages/gunicorn/util.py", line 352, in import_app
    __import__(module)
  File "/opt/weeklyreport/wsgi.py", line 5, in <module>
    app = create_app(os.getenv('FLASK_CONFIG') or 'default')
  File "/opt/weeklyreport/app/__init__.py", line 43, in create_app
    app.jinja_env.add_extension("chartkick.ext.charts")
  File "/usr/lib/python3.5/site-packages/jinja2/environment.py", line 345, in add_extension
    self.extensions.update(load_extensions(self, [extension]))
  File "/usr/lib/python3.5/site-packages/jinja2/environment.py", line 85, in load_extensions
    extension = import_string(extension)
  File "/usr/lib/python3.5/site-packages/jinja2/utils.py", line 143, in import_string
    return getattr(__import__(module, None, None, [obj]), obj)
ImportError: No module named 'chartkick'
[2017-04-11 14:02:35 +0800] [9] [INFO] Worker exiting (pid: 9)
